Workbook

Sheet Сводка
A1: Результаты прогона алгоритма при малых K
A2: M = 0,15·N, 3 seed на размер, средние по seed. Данные — лист «Результаты», пояснения — лист «Примечания».
A4: Эталон: прямое MILP (HiGHS через scipy)
A5: N | B5: Режим остановки | C5: Среднее время, с
A6: 100 | B6: =IF(COUNTIFS(Результаты!$A$2:$A$37,$A6,Результаты!$I$2:$I$37,"Да")=COUNTIFS(Результаты!$A$2:$A$37,$A6),"оптимум","лимит времени") -> оптимум | C6: =AVERAGEIFS(Результаты!$J$2:$J$37,Результаты!$A$2:$A$37,$A6) -> 1.0037285
A7: 300 | B7: =IF(COUNTIFS(Результаты!$A$2:$A$37,$A7,Результаты!$I$2:$I$37,"Да")=COUNTIFS(Результаты!$A$2:$A$37,$A7),"оптимум","лимит времени") -> лимит времени | C7: =AVERAGEIFS(Результаты!$J$2:$J$37,Результаты!$A$2:$A$37,$A7) -> 30.008178
A8: 1000 | B8: =IF(COUNTIFS(Результаты!$A$2:$A$37,$A8,Результаты!$I$2:$I$37,"Да")=COUNTIFS(Результаты!$A$2:$A$37,$A8),"оптимум","лимит времени") -> лимит времени | C8: =AVERAGEIFS(Результаты!$J$2:$J$37,Результаты!$A$2:$A$37,$A8) -> 30.031798
A9: 3000 | B9: =IF(COUNTIFS(Результаты!$A$2:$A$37,$A9,Результаты!$I$2:$I$37,"Да")=COUNTIFS(Результаты!$A$2:$A$37,$A9),"оптимум","лимит времени") -> лимит времени | C9: =AVERAGEIFS(Результаты!$J$2:$J$37,Результаты!$A$2:$A$37,$A9) -> 20.196831
A11: Среднее отклонение от прямого MILP (+ — алгоритм хуже, − — лучше)
A12: N | B12: 5 | C12: 10 | D12: 15
A13: 100 | B13: =AVERAGEIFS(Результаты!$K$2:$K$37,Результаты!$A$2:$A$37,$A13,Результаты!$D$2:$D$37,B$12) -> 0.019244964 | C13: =AVERAGEIFS(Результаты!$K$2:$K$37,Результаты!$A$2:$A$37,$A13,Результаты!$D$2:$D$37,C$12) -> 0.0053292105 | D13: =AVERAGEIFS(Результаты!$K$2:$K$37,Результаты!$A$2:$A$37,$A13,Результаты!$D$2:$D$37,D$12) -> 0.0053292105
A14: 300 | B14: =AVERAGEIFS(Результаты!$K$2:$K$37,Результаты!$A$2:$A$37,$A14,Результаты!$D$2:$D$37,B$12) -> 0.016865503 | C14: =AVERAGEIFS(Результаты!$K$2:$K$37,Результаты!$A$2:$A$37,$A14,Результаты!$D$2:$D$37,C$12) -> 0.0062448873 | D14: =AVERAGEIFS(Результаты!$K$2:$K$37,Результаты!$A$2:$A$37,$A14,Результаты!$D$2:$D$37,D$12) -> 0.0043792027
A15: 1000 | B15: =AVERAGEIFS(Результаты!$K$2:$K$37,Результаты!$A$2:$A$37,$A15,Результаты!$D$2:$D$37,B$12) -> 0.0027704781 | C15: =AVERAGEIFS(Результаты!$K$2:$K$37,Результаты!$A$2:$A$37,$A15,Результаты!$D$2:$D$37,C$12) -> 0.0012946874 | D15: =AVERAGEIFS(Результаты!$K$2:$K$37,Результаты!$A$2:$A$37,$A15,Результаты!$D$2:$D$37,D$12) -> 0.0012946874
A16: 3000 | B16: =AVERAGEIFS(Результаты!$K$2:$K$37,Результаты!$A$2:$A$37,$A16,Результаты!$D$2:$D$37,B$12) -> -0.0044745255 | C16: =AVERAGEIFS(Результаты!$K$2:$K$37,Результаты!$A$2:$A$37,$A16,Результаты!$D$2:$D$37,C$12) -> -0.005330685 | D16: =AVERAGEIFS(Результаты!$K$2:$K$37,Результаты!$A$2:$A$37,$A16,Результаты!$D$2:$D$37,D$12) -> -0.0058221491
A18: Средний gap к LP-границе
A19: N | B19: 5 | C19: 10 | D19: 15
A20: 100 | B20: =AVERAGEIFS(Результаты!$L$2:$L$37,Результаты!$A$2:$A$37,$A20,Результаты!$D$2:$D$37,B$19) -> 0.038338416 | C20: =AVERAGEIFS(Результаты!$L$2:$L$37,Результаты!$A$2:$A$37,$A20,Результаты!$D$2:$D$37,C$19) -> 0.024672008 | D20: =AVERAGEIFS(Результаты!$L$2:$L$37,Результаты!$A$2:$A$37,$A20,Результаты!$D$2:$D$37,D$19) -> 0.024672008
A21: 300 | B21: =AVERAGEIFS(Результаты!$L$2:$L$37,Результаты!$A$2:$A$37,$A21,Результаты!$D$2:$D$37,B$19) -> 0.026581793 | C21: =AVERAGEIFS(Результаты!$L$2:$L$37,Результаты!$A$2:$A$37,$A21,Результаты!$D$2:$D$37,C$19) -> 0.016066165 | D21: =AVERAGEIFS(Результаты!$L$2:$L$37,Результаты!$A$2:$A$37,$A21,Результаты!$D$2:$D$37,D$19) -> 0.01421903
A22: 1000 | B22: =AVERAGEIFS(Результаты!$L$2:$L$37,Результаты!$A$2:$A$37,$A22,Результаты!$D$2:$D$37,B$19) -> 0.0087663777 | C22: =AVERAGEIFS(Результаты!$L$2:$L$37,Результаты!$A$2:$A$37,$A22,Результаты!$D$2:$D$37,C$19) -> 0.0072990861 | D22: =AVERAGEIFS(Результаты!$L$2:$L$37,Результаты!$A$2:$A$37,$A22,Результаты!$D$2:$D$37,D$19) -> 0.0072990861
A23: 3000 | B23: =AVERAGEIFS(Результаты!$L$2:$L$37,Результаты!$A$2:$A$37,$A23,Результаты!$D$2:$D$37,B$19) -> 0.0043325149 | C23: =AVERAGEIFS(Результаты!$L$2:$L$37,Результаты!$A$2:$A$37,$A23,Результаты!$D$2:$D$37,C$19) -> 0.0034834299 | D23: =AVERAGEIFS(Результаты!$L$2:$L$37,Результаты!$A$2:$A$37,$A23,Результаты!$D$2:$D$37,D$19) -> 0.0029967138
A25: Среднее время алгоритма, с
A26: N | B26: 5 | C26: 10 | D26: 15
A27: 100 | B27: =AVERAGEIFS(Результаты!$F$2:$F$37,Результаты!$A$2:$A$37,$A27,Результаты!$D$2:$D$37,B$26) -> 0.011602958 | C27: =AVERAGEIFS(Результаты!$F$2:$F$37,Результаты!$A$2:$A$37,$A27,Результаты!$D$2:$D$37,C$26) -> 0.020437638 | D27: =AVERAGEIFS(Результаты!$F$2:$F$37,Результаты!$A$2:$A$37,$A27,Результаты!$D$2:$D$37,D$26) -> 0.019418716
A28: 300 | B28: =AVERAGEIFS(Результаты!$F$2:$F$37,Результаты!$A$2:$A$37,$A28,Результаты!$D$2:$D$37,B$26) -> 0.047588348 | C28: =AVERAGEIFS(Результаты!$F$2:$F$37,Результаты!$A$2:$A$37,$A28,Результаты!$D$2:$D$37,C$26) -> 0.057948589 | D28: =AVERAGEIFS(Результаты!$F$2:$F$37,Результаты!$A$2:$A$37,$A28,Результаты!$D$2:$D$37,D$26) -> 0.14184125
A29: 1000 | B29: =AVERAGEIFS(Результаты!$F$2:$F$37,Результаты!$A$2:$A$37,$A29,Результаты!$D$2:$D$37,B$26) -> 0.33659911 | C29: =AVERAGEIFS(Результаты!$F$2:$F$37,Результаты!$A$2:$A$37,$A29,Результаты!$D$2:$D$37,C$26) -> 0.32149752 | D29: =AVERAGEIFS(Результаты!$F$2:$F$37,Результаты!$A$2:$A$37,$A29,Результаты!$D$2:$D$37,D$26) -> 0.35856549
A30: 3000 | B30: =AVERAGEIFS(Результаты!$F$2:$F$37,Результаты!$A$2:$A$37,$A30,Результаты!$D$2:$D$37,B$26) -> 4.918363 | C30: =AVERAGEIFS(Результаты!$F$2:$F$37,Результаты!$A$2:$A$37,$A30,Результаты!$D$2:$D$37,C$26) -> 4.3908348 | D30: =AVERAGEIFS(Результаты!$F$2:$F$37,Результаты!$A$2:$A$37,$A30,Результаты!$D$2:$D$37,D$26) -> 4.1719178
A32: Среднее число LP-решений
A33: N | B33: 5 | C33: 10 | D33: 15
A34: 100 | B34: =AVERAGEIFS(Результаты!$N$2:$N$37,Результаты!$A$2:$A$37,$A34,Результаты!$D$2:$D$37,B$33) -> 16 | C34: =AVERAGEIFS(Результаты!$N$2:$N$37,Результаты!$A$2:$A$37,$A34,Результаты!$D$2:$D$37,C$33) -> 2 | D34: =AVERAGEIFS(Результаты!$N$2:$N$37,Результаты!$A$2:$A$37,$A34,Результаты!$D$2:$D$37,D$33) -> 2
A35: 300 | B35: =AVERAGEIFS(Результаты!$N$2:$N$37,Результаты!$A$2:$A$37,$A35,Результаты!$D$2:$D$37,B$33) -> 60.333333 | C35: =AVERAGEIFS(Результаты!$N$2:$N$37,Результаты!$A$2:$A$37,$A35,Результаты!$D$2:$D$37,C$33) -> 28 | D35: =AVERAGEIFS(Результаты!$N$2:$N$37,Результаты!$A$2:$A$37,$A35,Результаты!$D$2:$D$37,D$33) -> 7
A36: 1000 | B36: =AVERAGEIFS(Результаты!$N$2:$N$37,Результаты!$A$2:$A$37,$A36,Результаты!$D$2:$D$37,B$33) -> 62.666667 | C36: =AVERAGEIFS(Результаты!$N$2:$N$37,Результаты!$A$2:$A$37,$A36,Результаты!$D$2:$D$37,C$33) -> 45 | D36: =AVERAGEIFS(Результаты!$N$2:$N$37,Результаты!$A$2:$A$37,$A36,Результаты!$D$2:$D$37,D$33) -> 33
A37: 3000 | B37: =AVERAGEIFS(Результаты!$N$2:$N$37,Результаты!$A$2:$A$37,$A37,Результаты!$D$2:$D$37,B$33) -> 95 | C37: =AVERAGEIFS(Результаты!$N$2:$N$37,Результаты!$A$2:$A$37,$A37,Результаты!$D$2:$D$37,C$33) -> 74 | D37: =AVERAGEIFS(Результаты!$N$2:$N$37,Результаты!$A$2:$A$37,$A37,Результаты!$D$2:$D$37,D$33) -> 60.333333
A39: Среднее число возмущений (Шаг 2)
A40: N | B40: 5 | C40: 10 | D40: 15
A41: 100 | B41: =AVERAGEIFS(Результаты!$O$2:$O$37,Результаты!$A$2:$A$37,$A41,Результаты!$D$2:$D$37,B$40) -> 6.6666667 | C41: =AVERAGEIFS(Результаты!$O$2:$O$37,Результаты!$A$2:$A$37,$A41,Результаты!$D$2:$D$37,C$40) -> 0 | D41: =AVERAGEIFS(Результаты!$O$2:$O$37,Результаты!$A$2:$A$37,$A41,Результаты!$D$2:$D$37,D$40) -> 0
A42: 300 | B42: =AVERAGEIFS(Результаты!$O$2:$O$37,Результаты!$A$2:$A$37,$A42,Результаты!$D$2:$D$37,B$40) -> 31.666667 | C42: =AVERAGEIFS(Результаты!$O$2:$O$37,Результаты!$A$2:$A$37,$A42,Результаты!$D$2:$D$37,C$40) -> 10 | D42: =AVERAGEIFS(Результаты!$O$2:$O$37,Результаты!$A$2:$A$37,$A42,Результаты!$D$2:$D$37,D$40) -> 0
A43: 1000 | B43: =AVERAGEIFS(Результаты!$O$2:$O$37,Результаты!$A$2:$A$37,$A43,Результаты!$D$2:$D$37,B$40) -> 13.333333 | C43: =AVERAGEIFS(Результаты!$O$2:$O$37,Результаты!$A$2:$A$37,$A43,Результаты!$D$2:$D$37,C$40) -> 5 | D43: =AVERAGEIFS(Результаты!$O$2:$O$37,Результаты!$A$2:$A$37,$A43,Результаты!$D$2:$D$37,D$40) -> 0
A44: 3000 | B44: =AVERAGEIFS(Результаты!$O$2:$O$37,Результаты!$A$2:$A$37,$A44,Результаты!$D$2:$D$37,B$40) -> 18.666667 | C44: =AVERAGEIFS(Результаты!$O$2:$O$37,Результаты!$A$2:$A$37,$A44,Результаты!$D$2:$D$37,C$40) -> 7 | D44: =AVERAGEIFS(Результаты!$O$2:$O$37,Результаты!$A$2:$A$37,$A44,Результаты!$D$2:$D$37,D$40) -> 2
A46: Среднее число дайвов (Шаг 2′)
A47: N | B47: 5 | C47: 10 | D47: 15
...

Sheet Результаты
A1: N | B1: M | C1: Seed | D1: K | E1: Значение алгоритма | F1: Время алгоритма, с | G1: Прямое MILP, значение | H1: Оценка сверху (dual bound MILP) | I1: MILP доказал оптимум | J1: Время прямого MILP, с | K1: Отклонение от MILP | L1: Gap к LP-границе | M1: Отклонение от оценки сверху | N1: LP-решений | O1: Возмущений | P1: Дайвов (Шаг 2′) | Q1: Откатов
A2: 100 | B2: 15 | C2: 1 | D2: 5 | E2: 182 | F2: 0.014950037 | G2: 188 | H2: 188 | I2: Да | J2: 0.48953652 | K2: =(G2-E2)/ABS(G2) -> 0.031914894 | L2: 0.04761902 | M2: =(H2-E2)/H2 -> 0.031914894 | N2: 19 | O2: 10 | P2: 2 | Q2: 0
A3: 100 | B3: 15 | C3: 1 | D3: 10 | E3: 187 | F3: 0.015192032 | G3: 188 | H3: 188 | I3: Да | J3: 0.48953652 | K3: =(G3-E3)/ABS(G3) -> 0.0053191489 | L3: 0.021454708 | M3: =(H3-E3)/H3 -> 0.0053191489 | N3: 2 | O3: 0 | P3: 0 | Q3: 0
A4: 100 | B4: 15 | C4: 1 | D4: 15 | E4: 187 | F4: 0.014441252 | G4: 188 | H4: 188 | I4: Да | J4: 0.48953652 | K4: =(G4-E4)/ABS(G4) -> 0.0053191489 | L4: 0.021454708 | M4: =(H4-E4)/H4 -> 0.0053191489 | N4: 2 | O4: 0 | P4: 0 | Q4: 0
A5: 100 | B5: 15 | C5: 2 | D5: 5 | E5: 194 | F5: 0.0088398457 | G5: 198 | H5: 198 | I5: Да | J5: 1.1989002 | K5: =(G5-E5)/ABS(G5) -> 0.02020202 | L5: 0.040675726 | M5: =(H5-E5)/H5 -> 0.02020202 | N5: 15 | O5: 5 | P5: 1 | Q5: 0
A6: 100 | B6: 15 | C6: 2 | D6: 10 | E6: 197 | F6: 0.026117325 | G6: 198 | H6: 198 | I6: Да | J6: 1.1989002 | K6: =(G6-E6)/ABS(G6) -> 0.0050505051 | L6: 0.025840815 | M6: =(H6-E6)/H6 -> 0.0050505051 | N6: 2 | O6: 0 | P6: 0 | Q6: 0
A7: 100 | B7: 15 | C7: 2 | D7: 15 | E7: 197 | F7: 0.023541451 | G7: 198 | H7: 198 | I7: Да | J7: 1.1989002 | K7: =(G7-E7)/ABS(G7) -> 0.0050505051 | L7: 0.025840815 | M7: =(H7-E7)/H7 -> 0.0050505051 | N7: 2 | O7: 0 | P7: 0 | Q7: 0
A8: 100 | B8: 15 | C8: 3 | D8: 5 | E8: 177 | F8: 0.011018991 | G8: 178 | H8: 178 | I8: Да | J8: 1.3227487 | K8: =(G8-E8)/ABS(G8) -> 0.0056179775 | L8: 0.026720501 | M8: =(H8-E8)/H8 -> 0.0056179775 | N8: 14 | O8: 5 | P8: 1 | Q8: 0
A9: 100 | B9: 15 | C9: 3 | D9: 10 | E9: 177 | F9: 0.020003557 | G9: 178 | H9: 178 | I9: Да | J9: 1.3227487 | K9: =(G9-E9)/ABS(G9) -> 0.0056179775 | L9: 0.026720501 | M9: =(H9-E9)/H9 -> 0.0056179775 | N9: 2 | O9: 0 | P9: 0 | Q9: 0
A10: 100 | B10: 15 | C10: 3 | D10: 15 | E10: 177 | F10: 0.020273447 | G10: 178 | H10: 178 | I10: Да | J10: 1.3227487 | K10: =(G10-E10)/ABS(G10) -> 0.0056179775 | L10: 0.026720501 | M10: =(H10-E10)/H10 -> 0.0056179775 | N10: 2 | O10: 0 | P10: 0 | Q10: 0
A11: 300 | B11: 45 | C11: 1 | D11: 5 | E11: 529 | F11: 0.048662424 | G11: 538 | H11: 543 | I11: Нет | J11: 30.009243 | K11: =(G11-E11)/ABS(G11) -> 0.016728625 | L11: 0.026761284 | M11: =(H11-E11)/H11 -> 0.025782689 | N11: 59 | O11: 30 | P11: 6 | Q11: 0
A12: 300 | B12: 45 | C12: 1 | D12: 10 | E12: 535 | F12: 0.054073334 | G12: 538 | H12: 543 | I12: Нет | J12: 30.009243 | K12: =(G12-E12)/ABS(G12) -> 0.0055762082 | L12: 0.01572266 | M12: =(H12-E12)/H12 -> 0.014732965 | N12: 30 | O12: 10 | P12: 2 | Q12: 0
A13: 300 | B13: 45 | C13: 1 | D13: 15 | E13: 536 | F13: 0.13584757 | G13: 538 | H13: 543 | I13: Нет | J13: 30.009243 | K13: =(G13-E13)/ABS(G13) -> 0.0037174721 | L13: 0.013882889 | M13: =(H13-E13)/H13 -> 0.012891344 | N13: 11 | O13: 0 | P13: 0 | Q13: 0
... A37: 3000 | B37: 450 | C37: 3 | D37: 15 | E37: 5480 | F37: 3.8037732 | G37: 5456 | H37: 5497 | I37: Нет | J37: 20.207904 | K37: =(G37-E37)/ABS(G37) -> -0.004398827 | L37: 0.0031616815 | M37: =(H37-E37)/H37 -> 0.003092596 | N37: 52 | O37: 0 | P37: 0 | Q37: 0

Sheet Примечания
A1: Что это
A2: Результаты прогона прототипа binary_optimization_prototype.py (LP на HiGHS, персистентная модель) при малых K.
A3: Постановка
A4: max c·x при 0 ≤ Ax ≤ N, x ∈ {0,1}^N; c — целые 1…9, A — целые 0…9, M = 0,15·N; генерация numpy RandomState(seed), seed = 1, 2, 3.
A5: Параметры алгоритма
A6: K = 5, 10, 15; K_max = 2K; B_max = 3; ε = 1e-6; ρ̂ = 0,1; γ = 0,1; δ = 0,1; β = 2; R = 5; θ = 0,1; ζ = 0,05.
A7: Эталон
A8: Прямое MILP (scipy.optimize.milp) с лимитом времени 30 с для N ≤ 1000 и 20 с для N = 3000. При остановке по лимиту значение — лучшее найденное, не оптимум.
A9: «Оценка сверху» — dual bound HiGHS на момент остановки (при доказанном оптимуме совпадает со значением). Время прямого MILP измерено один раз на экземпляр и повторено в строках K = 5, 10, 15.
A10: Показатели
A11: Отклонение от MILP = (MILP − алгоритм) / |MILP|: плюс — алгоритм хуже эталона, минус — лучше (эталон на больших N не доведён до оптимума).
A12: Gap к LP-границе берётся из прогона: (z_LP − значение) / max(1, |z_LP|), где z_LP — оптимум LP-релаксации. Это верхняя оценка отклонения от истинного оптимума.
... A20: Откат на Шаге 3 не сработал ни разу: на задаче упаковки (A ≥ 0, ограничения ≤) фиксации округлением вниз всегда допустимы. Для проверки отката нужны задачи покрытия или назначения.
